Workbook
Name CASE: [1]LBO!$E$7
Name CIRC: [1]LBO!$E$6
Name PIK: [1]LBO!$E$8

Sheet LBO
B2: Hillside Private Capital - Husky Blue Diagnostics LBO Model
A4: x | B4: Assumptions
B6: Entry ($MM) | G6: Financials | L6: Capital Structure | N6: Amount | O6: 2026P Int. | P6: 2027P Int. | Q6: 2028P Int. | R6: 2029P Int. | S6: 2030P Int.
B7: LTM EBITDA | E7: =11.5259 -> 11.5259 | G7: Upside Investment Case | L7: Unitranche Term Loan | N7: 5 | O7: =4.5% + V9 -> 0.0814 | P7: =4.5% + V10 -> 0.0809 | Q7: =4.5% + V11 -> 0.08 | R7: =4.5% + V12 -> 0.08 | S7: =4.5% + V13 -> 0.08 | U7: Rate Inputs
B8: EBITDA Multiple | E8: 8.5 | G8: Revenue | J8: 68.38 | U8: Year | V8: SOFR | X8: Notes
B9: Enterprise Value | E9: =E7*E8 -> 97.97015 | G9: EBITDA | J9: 11.5259 | U9: Year 1 | V9: 0.0364 | X9: 65% recurring compliance revenue
B10: Existing Net Debt | E10: 13 | G10: D&A | J10: 2.85 | L10: For Reference | U10: Year 2 | V10: 0.0359 | X10: 60% of customer base renews in 2027
B11: Equity Value | E11: =E9-E10 -> 84.97015 | G11: Capex | J11: 5.1285 | L11: IRR | O11: =O109 -> 0.2226171 | U11: Year 3 | V11: 0.035 | X11: Existing net debt to refi = $13.0mm
B12: Transaction Fees & Expenses | E12: =0.02*E27 -> 1.1003458 | G12: NWC | J12: 1.7095 | U12: Year 4 | V12: 0.035 | X12: No mandatory amortization
U13: Year 5 | V13: 0.035 | X13: Debt fees = 1.0%; sponsor fees = 2.0%
G14: Operating Assumptions
B15: Exit ($MM) | G15: YoY margin expansion | J15: 0.01
B16: EBITDA Multiple | E16: 8.5 | G16: Tax Rate | J16: 0.21
A19: x | B19: Sources and Uses
B21: Sources | J21: Uses
E22: Amount | F22: xEBITDA | G22: % Capital | M22: Amount | N22: xEBITDA | O22: % Capital
B23: Unitranche Term Loan | E23: =N7*$E$7 -> 57.6295 | F23: =E23/$E$7 -> 5 | G23: =E23/$E$29 -> 0.51159469 | J23: Purchase Price | M23: =E9 -> 97.97015 | N23: =M23/$E$7 -> 8.5 | O23: =M23/$M$29 -> 0.86971097
J24: Refi Existing Net Debt | M24: =E10 -> 13 | N24: =M24/$E$7 -> 1.1278946 | O24: =M24/$M$29 -> 0.11540497
B25: Total Debt | E25: =SUM(E23:E24) -> 57.6295 | F25: =SUM(F23:F24) -> 5 | G25: =SUM(G23:G24) -> 0.51159469 | J25: Debt Fees | M25: =J15*E25 -> 0.576295 | N25: =M25/$E$7 -> 0.05 | O25: =M25/$M$29 -> 0.0051159469
J26: Transaction Fees | M26: =E12 -> 1.1003458 | N26: =M26/$E$7 -> 0.095467236 | O26: =M26/$M$29 -> 0.0097681062
B27: Sponsor Equity | E27: =M29-E25 -> 55.017291 | F27: =E27/$E$7 -> 4.7733618 | G27: =E27/$E$29 -> 0.48840531
B29: Total Sources | E29: =SUM(E25:E27) -> 112.64679 | F29: =SUM(F25:F27) -> 9.7733618 | G29: =SUM(G25:G27) -> 1 | J29: Total Uses | M29: =SUM(M23:M26) -> 112.64679 | N29: =SUM(N23:N26) -> 9.7733618 | O29: =SUM(O23:O26) -> 1
A32: x | B32: Financials
B34: Operating Model | J34: 2025A | K34: 2026P | L34: 2027P | M34: 2028P | N34: 2029P | O34: 2030P
B35: Revenue | J35: =J8 -> 68.38 | K35: =J35*(1+J36) -> 74.8761 | L35: =K35*(1+K36) -> 81.614949 | M35: =L35*(1+L36) -> 88.960294 | N35: =M35*(1+M36) -> 97.856324 | O35: =N35*(1+N36) -> 108.62052
B36: % growth | J36: 0.095 | K36: 0.09 | L36: 0.09 | M36: 0.1 | N36: 0.11 | O36: 0.1 | Q36: 0.01 | R36: < 2027 step-up | T36: 0.01 | U36: < 2028 stepup
B38: EBITDA | J38: =J9 -> 11.5259 | K38: =K35*K39 -> 11.456043 | L38: =L35*L39 -> 13.874541 | M38: =M35*M39 -> 15.568052 | N38: =N35*N39 -> 17.614138 | O38: =O35*O39 -> 18.79135
B39: % sales | J39: =J9/J8 -> 0.1685566 | K39: 0.153 | L39: 0.17 | M39: 0.175 | N39: 0.18 | O39: 0.173
B41: EBIT | J41: =J38-J56 -> 8.6759 | K41: =K38-K56 -> 8.3060433 | L41: =L38-L56 -> 10.474541 | M41: =M38-M56 -> 11.918052 | N41: =N38-N56 -> 13.734138 | O41: =O38-O56 -> 14.75615
B42: % sales | J42: =J41/J35 -> 0.12687774 | K42: =K41/K35 -> 0.1109305 | L42: =L41/L35 -> 0.12834097 | M42: =M41/M35 -> 0.13397046 | N42: =N41/N35 -> 0.14035003 | O42: =O41/O35 -> 0.13585048
B44: Interest | J44: 0 | K44: =K92 -> 4.6910413 | L44: =L92 -> 4.5589976 | M44: =M92 -> 4.2681856 | N44: =N92 -> 3.9350018 | O44: =O92 -> 3.4935105
B46: EBT | J46: =J41-J44 -> 8.6759 | K46: =K41-K44 -> 3.615002 | L46: =L41-L44 -> 5.9155437 | M46: =M41-M44 -> 7.6498659 | N46: =N41-N44 -> 9.7991364 | O46: =O41-O44 -> 11.262639
B47: % sales | J47: =J46/J35 -> 0.12687774 | K47: =K46/K35 -> 0.048279785 | L47: =L46/L35 -> 0.07248113 | M47: =M46/M35 -> 0.085991913 | N47: =N46/N35 -> 0.100138 | O47: =O46/O35 -> 0.10368795
B49: Taxes | J49: =$J$16 * J46 -> 1.821939 | K49: =MAX(0,K46*K50) -> 0.75915042 | L49: =MAX(0,L46*L50) -> 1.2422642 | M49: =MAX(0,M46*M50) -> 1.6064718 | N49: =MAX(0,N46*N50) -> 2.0578187 | O49: =MAX(0,O46*O50) -> 2.3651543
B50: % tax rate | J50: =$J$16 -> 0.21 | K50: =$J$16 -> 0.21 | L50: =$J$16 -> 0.21 | M50: =$J$16 -> 0.21 | N50: =$J$16 -> 0.21 | O50: =$J$16 -> 0.21
B52: Net Income | J52: =J46-J49 -> 6.853961 | K52: =K46-K49 -> 2.8558516 | L52: =L46-L49 -> 4.6732796 | M52: =M46-M49 -> 6.043394 | N52: =N46-N49 -> 7.7413178 | O52: =O46-O49 -> 8.8974851
B53: % sales | J53: =J52/J35 -> 0.10023342 | K53: =K52/K35 -> 0.03814103 | L53: =L52/L35 -> 0.057260093 | M53: =M52/M35 -> 0.067933611 | N53: =N52/N35 -> 0.079109019 | O53: =O52/O35 -> 0.081913483
A55: x | B55: Cash flow Items | J55: Year 0 | K55: Year 1 | L55: Year 2 | M55: Year 3 | N55: Year 4 | O55: Year 5
B56: D&A | J56: 2.85 | K56: 3.15 | L56: 3.4 | M56: 3.65 | N56: 3.88 | O56: 4.0352
B57: % sales | J57: =J56/J35 -> 0.041678853 | K57: =K56/K35 -> 0.042069499 | L57: =L56/L35 -> 0.041659035 | M57: =M56/M35 -> 0.04102954 | N57: =N56/N35 -> 0.039649967 | O57: =O56/O35 -> 0.037149519
...

Sheet Stress Test
B2: HPC LBO — Stress Test Operating Model | Management / Base / Downside
B4: SECTION 1 — CASE ASSUMPTIONS (Blue = inputs | Green = linked from LBO)
B5: Driver | C5: Base | D5: Upside | E5: Downside
B6: Active Case → | C6: UPSIDE | D6: ← Type: Base / Upside / Downside
B7: ▸ Revenue Growth
B8: Revenue Growth Yr1 | C8: 0.08 | D8: 0.09 | E8: 0.05
B9: Revenue Growth Yr2 | C9: 0.06 | D9: 0.09 | E9: 0.03
B10: Revenue Growth Yr3 | C10: 0.05 | D10: 0.1 | E10: 0.02
B11: Revenue Growth Yr4 | C11: 0.05 | D11: 0.11 | E11: 0.02
B12: Revenue Growth Yr5 | C12: 0.04 | D12: 0.1 | E12: 0.02
B13: ▸ EBITDA Margin
B14: Entry EBITDA Margin | C14: 0.153 | D14: 0.153 | E14: 0.14
B15: Yr2 Margin | C15: 0.158 | D15: 0.158 | E15: 0.145
B16: Yr3 Margin | C16: 0.163 | D16: 0.163 | E16: 0.15
B17: Yr4 Margin | C17: 0.168 | D17: 0.168 | E17: 0.155
B18: Yr5 Margin | C18: 0.168 | D18: 0.173 | E18: 0.155
B19: ▸ CapEx, NWC & Exit
B20: CapEx Yr1 % Rev | C20: 0.065 | D20: 0.06 | E20: 0.075
B21: CapEx Yr2-5 % Rev | C21: 0.06 | D21: 0.06 | E21: 0.075
B22: NWC % Rev | C22: 0.026 | D22: 0.026 | E22: 0.028
B23: Exit EV/EBITDA | C23: 8.5 | D23: 8.5 | E23: 8.5
B24: ▸ Fixed Inputs (linked from LBO)
B25: LTM EBITDA ($MM) | C25: =LBO!E7 -> 11.5259
B26: Entry EV/EBITDA | C26: =LBO!E8 -> 8.5
B27: Initial Debt ($MM) | C27: =LBO!E23 -> 57.6295
B28: Sponsor Equity ($MM) | C28: =LBO!E27 -> 55.017291
B29: Entry NWC ($MM) | C29: =LBO!J12 -> 1.7095
B31: SECTION 2 — OPERATING MODEL (mirrors LBO structure)
C32: Year 1 | D32: Year 2 | E32: Year 3 | F32: Year 4 | G32: Year 5 | I32: Returns Summary | J32: Mgmt | K32: Base | L32: Downside
B33: ▸ Revenue ($MM) | I33: EXIT METRICS
B34: Management | C34: =LBO!J8*(1+C8) -> 73.8504 | D34: =C34*(1+C9) -> 78.281424 | E34: =D34*(1+C10) -> 82.195495 | F34: =E34*(1+C11) -> 86.30527 | G34: =F34*(1+C12) -> 89.757481 | I34: Exit EBITDA ($MM) | J34: =C114 -> 15.079257 | K34: =D114 -> 18.79135 | L34: =E114 -> 12.16432
B35: Base | C35: =LBO!K35 -> 74.8761 | D35: =LBO!L35 -> 81.614949 | E35: =LBO!M35 -> 88.960294 | F35: =LBO!N35 -> 97.856324 | G35: =LBO!O35 -> 108.62052 | I35: Exit EV/EBITDA | J35: =C115 -> 8.5 | K35: =D115 -> 8.5 | L35: =E115 -> 8.5
B36: Downside | C36: =LBO!J8*(1+E8) -> 71.799 | D36: =C36*(1+E9) -> 73.95297 | E36: =D36*(1+E10) -> 75.432029 | F36: =E36*(1+E11) -> 76.94067 | G36: =F36*(1+E12) -> 78.479483 | I36: Exit EV ($MM) | J36: =C116 -> 128.17368 | K36: =D116 -> 159.72647 | L36: =E116 -> 103.39672
B37: ▸ EBITDA ($MM) | I37: Net Debt at Exit ($MM) | J37: =C117 -> 43.904701 | K37: =D117 -> 37.533297 | L37: =E117 -> 56.018771
B38: Management | C38: =C34*C14 -> 11.299111 | D38: =D34*C15 -> 12.368465 | E38: =E34*C16 -> 13.397866 | F38: =F34*C17 -> 14.499285 | G38: =G34*C18 -> 15.079257 | I38: Equity Value ($MM) | J38: =C118 -> 84.268981 | K38: =D118 -> 122.19318 | L38: =E118 -> 47.377948
B39: Base | C39: =LBO!K38 -> 11.456043 | D39: =LBO!L38 -> 13.874541 | E39: =LBO!M38 -> 15.568052 | F39: =LBO!N38 -> 17.614138 | G39: =LBO!O38 -> 18.79135
B40: Downside | C40: =C36*E14 -> 10.05186 | D40: =D36*E15 -> 10.723181 | E40: =E36*E16 -> 11.314804 | F40: =F36*E17 -> 11.925804 | G40: =G36*E18 -> 12.16432 | I40: RETURNS
B41: ▸ EBITDA Margin (%) | I41: Equity MOIC | J41: =C119 -> 1.5316818 | K41: =D119 -> 2.2209959 | L41: =E119 -> 0.86114652
B42: Management | C42: =C38/C34 -> 0.153 | D42: =D38/D34 -> 0.158 | E42: =E38/E34 -> 0.163 | F42: =F38/F34 -> 0.168 | G42: =G38/G34 -> 0.168 | I42: Equity IRR (XIRR) | J42: =C124 -> 0.088963762 | K42: =D124 -> 0.2226171 | L42: =E124 -> -0.029439703
B43: Base | C43: =C39/C35 -> 0.153 | D43: =D39/D35 -> 0.17 | E43: =E39/E35 -> 0.175 | F43: =F39/F35 -> 0.18 | G43: =G39/G35 -> 0.173 | I43: Debt IRR | J43: =C125 -> 0.080563457 | K43: =D125 -> 0.080563457 | L43: =E125 -> 0.080563457
...

Sheet PublicComp Table
A1: Company | B1: Market Cap ($M) | C1: EV ($M) | D1: Net Debt ($M) | E1: EV / Revenue (LTM) | F1: EV / EBITDA (LTM)
A2: SGS S.A. | B2: 19654 | C2: 23112 | D2: 3575 | E2: 2.7 | F2: 13
A3: Bureau Veritas S.A. | B3: 15253 | C3: 17287 | D3: 2017 | E3: 2.2 | F3: 11.7
A4: Intertek Group PLC | B4: 10197 | C4: 11351 | D4: 1481 | E4: 2.4 | F4: 11.2
A5: Mistras Group, Inc. | B5: 251 | C5: 470 | D5: 191 | E5: 0.7 | F5: 5.6
A7: Mean | E7: =AVERAGE(E2:E5) -> 2 | F7: =AVERAGE(F2:F5) -> 10.375
A8: Median | E8: =MEDIAN(E2:E5) -> 2.3 | F8: =MEDIAN(F2:F5) -> 11.45
A9: Max | E9: =MIN(E2:E5) -> 0.7 | F9: =MIN(F2:F5) -> 5.6
A10: Min | E10: =MAX(E2:E5) -> 2.7 | F10: =MAX(F2:F5) -> 13
